2017-11-26 21:48:54 - (sanic)[DEBUG]: 
                 ▄▄▄▄▄
        ▀▀▀██████▄▄▄       _______________
      ▄▄▄▄▄  █████████▄  /                 \
     ▀▀▀▀█████▌ ▀▐▄ ▀▐█ |   Gotta go fast!  |
   ▀▀█████▄▄ ▀██████▄██ | _________________/
   ▀▄▄▄▄▄  ▀▀█▄▀█════█▀ |/
        ▀▀▀▄  ▀▀███ ▀       ▄▄
     ▄███▀▀██▄████████▄ ▄▀▀▀▀▀▀█▌
   ██▀▄▄▄██▀▄███▀ ▀▀████      ▄██
▄▀▀▀▄██▄▀▀▌████▒▒▒▒▒▒███     ▌▄▄▀
▌    ▐▀████▐███▒▒▒▒▒▐██▌
▀▄▄▄▄▀   ▀▀████▒▒▒▒▄██▀
          ▀▀█████████▀
        ▄▄██▀██████▀█
      ▄██▀     ▀▀▀  █
     ▄█             ▐▌
 ▄▄▄▄█▌              ▀█▄▄▄▄▀▀▄
▌     ▐                ▀▀▄▄▄▀
 ▀▀▄▄▀

2017-11-26 21:48:54 - (sanic)[INFO]: Goin' Fast @ http://0.0.0.0:8080
2017-11-26 21:48:54 - (sanic)[INFO]: Starting worker [22345]
2017-11-26 21:48:54 - (sanic)[INFO]: Starting worker [22344]
2017-11-26 21:48:54 - (sanic)[INFO]: Starting worker [22346]
2017-11-26 21:48:54 - (sanic)[INFO]: Starting worker [22347]
/home/ubuntu/calculator/service/compute.py:51: RuntimeWarning: invalid value encountered in less
  points[points < -y_bounds] = np.nan
Executing <Handle <TaskStepMethWrapper object at 0x7f57963c5160> created at /home/ubuntu/anaconda3/lib/python3.6/site-packages/sanic/server.py:234> took 0.231 seconds
2017-11-26 21:49:02 - (network)[INFO][129.174.182.39:28002]: GET http://54.189.255.114:8080/graph?exp=tan(x)  200 28315
2017-11-26 21:49:08 - (sanic)[INFO]: Received signal SIGINT. Shutting down.
2017-11-26 21:49:08 - (sanic)[INFO]: Stopping worker [22347]
2017-11-26 21:49:08 - (sanic)[INFO]: Stopping worker [22346]
2017-11-26 21:49:08 - (sanic)[INFO]: Stopping worker [22345]
2017-11-26 21:49:08 - (sanic)[INFO]: Stopping worker [22344]
2017-11-26 21:49:08 - (sanic)[INFO]: Server Stopped
2017-11-26 21:49:22 - (sanic)[DEBUG]: 
                 ▄▄▄▄▄
        ▀▀▀██████▄▄▄       _______________
      ▄▄▄▄▄  █████████▄  /                 \
     ▀▀▀▀█████▌ ▀▐▄ ▀▐█ |   Gotta go fast!  |
   ▀▀█████▄▄ ▀██████▄██ | _________________/
   ▀▄▄▄▄▄  ▀▀█▄▀█════█▀ |/
        ▀▀▀▄  ▀▀███ ▀       ▄▄
     ▄███▀▀██▄████████▄ ▄▀▀▀▀▀▀█▌
   ██▀▄▄▄██▀▄███▀ ▀▀████      ▄██
▄▀▀▀▄██▄▀▀▌████▒▒▒▒▒▒███     ▌▄▄▀
▌    ▐▀████▐███▒▒▒▒▒▐██▌
▀▄▄▄▄▀   ▀▀████▒▒▒▒▄██▀
          ▀▀█████████▀
        ▄▄██▀██████▀█
      ▄██▀     ▀▀▀  █
     ▄█             ▐▌
 ▄▄▄▄█▌              ▀█▄▄▄▄▀▀▄
▌     ▐                ▀▀▄▄▄▀
 ▀▀▄▄▀

2017-11-26 21:49:22 - (sanic)[INFO]: Goin' Fast @ http://0.0.0.0:8080
2017-11-26 21:49:22 - (sanic)[INFO]: Starting worker [22356]
2017-11-26 21:49:22 - (sanic)[INFO]: Starting worker [22357]
2017-11-26 21:49:22 - (sanic)[INFO]: Starting worker [22358]
2017-11-26 21:49:22 - (sanic)[INFO]: Starting worker [22355]
/home/ubuntu/calculator/service/compute.py:51: RuntimeWarning: invalid value encountered in less
  points[points < -y_bounds] = np.nan
Executing <Handle <TaskStepMethWrapper object at 0x7f4506315320> created at /home/ubuntu/anaconda3/lib/python3.6/site-packages/sanic/server.py:234> took 0.232 seconds
2017-11-26 21:49:32 - (network)[INFO][129.174.182.39:19235]: GET http://54.189.255.114:8080/graph?exp=tan(x)  200 28315
/home/ubuntu/calculator/service/compute.py:51: RuntimeWarning: invalid value encountered in less
  points[points < -y_bounds] = np.nan
Executing <Handle <TaskStepMethWrapper object at 0x7f45063155f8> created at /home/ubuntu/anaconda3/lib/python3.6/site-packages/sanic/server.py:234> took 0.295 seconds
2017-11-26 21:49:46 - (network)[INFO][129.174.182.39:19235]: GET http://54.189.255.114:8080/graph?exp=tan(x)  200 28284
/home/ubuntu/calculator/service/compute.py:51: RuntimeWarning: invalid value encountered in less
  points[points < -y_bounds] = np.nan
Executing <Handle <TaskStepMethWrapper object at 0x7f45063157f0> created at /home/ubuntu/anaconda3/lib/python3.6/site-packages/sanic/server.py:234> took 0.231 seconds
2017-11-26 21:50:36 - (network)[INFO][129.174.182.76:28866]: GET http://54.189.255.114:8080/graph?exp=5x%2B2  200 19949
2017-11-26 21:50:47 - (sanic)[ERROR]: Traceback (most recent call last):
  File "/home/ubuntu/anaconda3/lib/python3.6/site-packages/sanic/server.py", line 143, in connection_timeout
    raise RequestTimeout('Request Timeout')
sanic.exceptions.RequestTimeout: Request Timeout

2017-11-26 21:51:36 - (sanic)[ERROR]: Traceback (most recent call last):
  File "/home/ubuntu/anaconda3/lib/python3.6/site-packages/sanic/server.py", line 143, in connection_timeout
    raise RequestTimeout('Request Timeout')
sanic.exceptions.RequestTimeout: Request Timeout

2017-11-26 21:51:37 - (sanic)[INFO]: Stopping worker [22357]
2017-11-26 21:51:37 - (sanic)[INFO]: Received signal SIGINT. Shutting down.
2017-11-26 21:51:37 - (sanic)[INFO]: Stopping worker [22355]
2017-11-26 21:51:37 - (sanic)[INFO]: Stopping worker [22358]
2017-11-26 21:51:37 - (sanic)[INFO]: Stopping worker [22356]
2017-11-26 21:51:37 - (sanic)[INFO]: Server Stopped
2017-11-26 21:51:43 - (sanic)[DEBUG]: 
                 ▄▄▄▄▄
        ▀▀▀██████▄▄▄       _______________
      ▄▄▄▄▄  █████████▄  /                 \
     ▀▀▀▀█████▌ ▀▐▄ ▀▐█ |   Gotta go fast!  |
   ▀▀█████▄▄ ▀██████▄██ | _________________/
   ▀▄▄▄▄▄  ▀▀█▄▀█════█▀ |/
        ▀▀▀▄  ▀▀███ ▀       ▄▄
     ▄███▀▀██▄████████▄ ▄▀▀▀▀▀▀█▌
   ██▀▄▄▄██▀▄███▀ ▀▀████      ▄██
▄▀▀▀▄██▄▀▀▌████▒▒▒▒▒▒███     ▌▄▄▀
▌    ▐▀████▐███▒▒▒▒▒▐██▌
▀▄▄▄▄▀   ▀▀████▒▒▒▒▄██▀
          ▀▀█████████▀
        ▄▄██▀██████▀█
      ▄██▀     ▀▀▀  █
     ▄█             ▐▌
 ▄▄▄▄█▌              ▀█▄▄▄▄▀▀▄
▌     ▐                ▀▀▄▄▄▀
 ▀▀▄▄▀

2017-11-26 21:51:43 - (sanic)[INFO]: Goin' Fast @ http://0.0.0.0:8080
2017-11-26 21:51:43 - (sanic)[INFO]: Starting worker [22371]
2017-11-26 21:51:43 - (sanic)[INFO]: Starting worker [22370]
2017-11-26 21:51:43 - (sanic)[INFO]: Starting worker [22373]
2017-11-26 21:51:43 - (sanic)[INFO]: Starting worker [22372]
/home/ubuntu/calculator/service/compute.py:51: RuntimeWarning: invalid value encountered in less
  points[points < -y_bounds] = np.nan
Executing <Handle <TaskStepMethWrapper object at 0x7ff1bda20160> created at /home/ubuntu/anaconda3/lib/python3.6/site-packages/sanic/server.py:234> took 0.236 seconds
2017-11-26 21:51:49 - (network)[INFO][129.174.182.39:37495]: GET http://54.189.255.114:8080/graph?exp=tan(x)  200 28315
/home/ubuntu/calculator/service/compute.py:51: RuntimeWarning: invalid value encountered in less
  points[points < -y_bounds] = np.nan
Executing <Handle <TaskStepMethWrapper object at 0x7ff1bda20240> created at /home/ubuntu/anaconda3/lib/python3.6/site-packages/sanic/server.py:234> took 0.300 seconds
2017-11-26 21:51:51 - (network)[INFO][129.174.182.39:37495]: GET http://54.189.255.114:8080/graph?exp=tan(x)  200 28284
Executing <Handle <TaskStepMethWrapper object at 0x7ff1bda20630> created at /home/ubuntu/anaconda3/lib/python3.6/site-packages/sanic/server.py:234> took 0.401 seconds
2017-11-26 21:51:54 - (network)[INFO][129.174.182.39:37495]: GET http://54.189.255.114:8080/graph?exp=tan(x)  200 28208
Executing <Handle <TaskStepMethWrapper object at 0x7ff1c63eb0f0> created at /home/ubuntu/anaconda3/lib/python3.6/site-packages/sanic/server.py:234> took 0.519 seconds
2017-11-26 21:52:15 - (network)[INFO][129.174.182.39:37495]: GET http://54.189.255.114:8080/graph?exp=tan(x)  200 28179
Executing <Handle <TaskStepMethWrapper object at 0x7ff1c63e0f28> created at /home/ubuntu/anaconda3/lib/python3.6/site-packages/sanic/server.py:234> took 0.624 seconds
2017-11-26 21:52:33 - (network)[INFO][129.174.182.39:37495]: GET http://54.189.255.114:8080/graph?exp=tan(x)  200 28138
Executing <Handle <TaskStepMethWrapper object at 0x7ff1bb697320> created at /home/ubuntu/anaconda3/lib/python3.6/site-packages/sanic/server.py:234> took 0.740 seconds
2017-11-26 21:52:35 - (network)[INFO][129.174.182.39:37495]: GET http://54.189.255.114:8080/graph?exp=tan(x)  200 28071
Executing <Handle <TaskStepMethWrapper object at 0x7ff1bd6ef400> created at /home/ubuntu/anaconda3/lib/python3.6/site-packages/sanic/server.py:234> took 0.851 seconds
2017-11-26 21:52:52 - (network)[INFO][129.174.182.39:37495]: GET http://54.189.255.114:8080/graph?exp=sin(x)  200 17587
Executing <Handle <TaskStepMethWrapper object at 0x7ff1bd6e93c8> created at /home/ubuntu/anaconda3/lib/python3.6/site-packages/sanic/server.py:234> took 0.950 seconds
2017-11-26 21:53:06 - (network)[INFO][129.174.182.39:37495]: GET http://54.189.255.114:8080/graph?exp=sin(x)  200 17589
Executing <Handle <TaskStepMethWrapper object at 0x7ff1bb697320> created at /home/ubuntu/anaconda3/lib/python3.6/site-packages/sanic/server.py:234> took 1.062 seconds
2017-11-26 21:53:28 - (network)[INFO][129.174.182.39:37495]: GET http://54.189.255.114:8080/graph?exp=x  200 20164
2017-11-26 21:54:29 - (sanic)[ERROR]: Traceback (most recent call last):
  File "/home/ubuntu/anaconda3/lib/python3.6/site-packages/sanic/server.py", line 143, in connection_timeout
    raise RequestTimeout('Request Timeout')
sanic.exceptions.RequestTimeout: Request Timeout

Executing <Handle <TaskStepMethWrapper object at 0x7ff1bda20550> created at /home/ubuntu/anaconda3/lib/python3.6/site-packages/sanic/server.py:234> took 0.234 seconds
2017-11-26 22:14:53 - (network)[INFO][174.204.6.241:1570]: GET http://54.189.255.114:8080/graph?exp=x  200 20410
2017-11-26 22:15:53 - (sanic)[ERROR]: Traceback (most recent call last):
  File "/home/ubuntu/anaconda3/lib/python3.6/site-packages/sanic/server.py", line 143, in connection_timeout
    raise RequestTimeout('Request Timeout')
sanic.exceptions.RequestTimeout: Request Timeout

/home/ubuntu/calculator/service/compute.py:51: RuntimeWarning: invalid value encountered in less
  points[points < -y_bounds] = np.nan
Executing <Handle <TaskStepMethWrapper object at 0x7ff1bda20630> created at /home/ubuntu/anaconda3/lib/python3.6/site-packages/sanic/server.py:234> took 0.221 seconds
2017-11-26 22:31:57 - (network)[INFO][129.174.182.76:42401]: GET http://54.189.255.114:8080/graph?exp=x^2  200 18490
2017-11-26 22:32:57 - (sanic)[ERROR]: Traceback (most recent call last):
  File "/home/ubuntu/anaconda3/lib/python3.6/site-packages/sanic/server.py", line 143, in connection_timeout
    raise RequestTimeout('Request Timeout')
sanic.exceptions.RequestTimeout: Request Timeout

Executing <Handle <TaskStepMethWrapper object at 0x7ff1bda20438> created at /home/ubuntu/anaconda3/lib/python3.6/site-packages/sanic/server.py:234> took 0.231 seconds
2017-11-26 23:05:18 - (network)[INFO][174.204.6.241:11214]: GET http://54.189.255.114:8080/graph?exp=x  200 20410
2017-11-26 23:06:18 - (sanic)[ERROR]: Traceback (most recent call last):
  File "/home/ubuntu/anaconda3/lib/python3.6/site-packages/sanic/server.py", line 143, in connection_timeout
    raise RequestTimeout('Request Timeout')
sanic.exceptions.RequestTimeout: Request Timeout

2017-11-26 23:06:19 - (sanic)[INFO]: Received signal SIGTERM. Shutting down.
2017-11-26 23:06:19 - (sanic)[INFO]: Stopping worker [22372]
2017-11-26 23:06:19 - (sanic)[INFO]: Stopping worker [22373]
2017-11-26 23:06:19 - (sanic)[INFO]: Stopping worker [22370]
2017-11-26 23:06:19 - (sanic)[INFO]: Stopping worker [22371]
2017-11-26 23:06:19 - (sanic)[INFO]: Server Stopped
