2017-11-26 21:48:54 - (sanic)[DEBUG]: 
                 ▄▄▄▄▄
        ▀▀▀██████▄▄▄       _______________
      ▄▄▄▄▄  █████████▄  /                 \
     ▀▀▀▀█████▌ ▀▐▄ ▀▐█ |   Gotta go fast!  |
   ▀▀█████▄▄ ▀██████▄██ | _________________/
   ▀▄▄▄▄▄  ▀▀█▄▀█════█▀ |/
        ▀▀▀▄  ▀▀███ ▀       ▄▄
     ▄███▀▀██▄████████▄ ▄▀▀▀▀▀▀█▌
   ██▀▄▄▄██▀▄███▀ ▀▀████      ▄██
▄▀▀▀▄██▄▀▀▌████▒▒▒▒▒▒███     ▌▄▄▀
▌    ▐▀████▐███▒▒▒▒▒▐██▌
▀▄▄▄▄▀   ▀▀████▒▒▒▒▄██▀
          ▀▀█████████▀
        ▄▄██▀██████▀█
      ▄██▀     ▀▀▀  █
     ▄█             ▐▌
 ▄▄▄▄█▌              ▀█▄▄▄▄▀▀▄
▌     ▐                ▀▀▄▄▄▀
 ▀▀▄▄▀

2017-11-26 21:48:54 - (sanic)[INFO]: Goin' Fast @ http://0.0.0.0:8080
2017-11-26 21:48:54 - (sanic)[INFO]: Starting worker [22345]
2017-11-26 21:48:54 - (sanic)[INFO]: Starting worker [22344]
2017-11-26 21:48:54 - (sanic)[INFO]: Starting worker [22346]
2017-11-26 21:48:54 - (sanic)[INFO]: Starting worker [22347]
/home/ubuntu/calculator/service/compute.py:51: RuntimeWarning: invalid value encountered in less
  points[points < -y_bounds] = np.nan
Executing <Handle <TaskStepMethWrapper object at 0x7f57963c5160> created at /home/ubuntu/anaconda3/lib/python3.6/site-packages/sanic/server.py:234> took 0.231 seconds
2017-11-26 21:49:02 - (network)[INFO][129.174.182.39:28002]: GET http://54.189.255.114:8080/graph?exp=tan(x)  200 28315
2017-11-26 21:49:08 - (sanic)[INFO]: Received signal SIGINT. Shutting down.
2017-11-26 21:49:08 - (sanic)[INFO]: Stopping worker [22347]
2017-11-26 21:49:08 - (sanic)[INFO]: Stopping worker [22346]
2017-11-26 21:49:08 - (sanic)[INFO]: Stopping worker [22345]
2017-11-26 21:49:08 - (sanic)[INFO]: Stopping worker [22344]
2017-11-26 21:49:08 - (sanic)[INFO]: Server Stopped
2017-11-26 21:49:22 - (sanic)[DEBUG]: 
                 ▄▄▄▄▄
        ▀▀▀██████▄▄▄       _______________
      ▄▄▄▄▄  █████████▄  /                 \
     ▀▀▀▀█████▌ ▀▐▄ ▀▐█ |   Gotta go fast!  |
   ▀▀█████▄▄ ▀██████▄██ | _________________/
   ▀▄▄▄▄▄  ▀▀█▄▀█════█▀ |/
        ▀▀▀▄  ▀▀███ ▀       ▄▄
     ▄███▀▀██▄████████▄ ▄▀▀▀▀▀▀█▌
   ██▀▄▄▄██▀▄███▀ ▀▀████      ▄██
▄▀▀▀▄██▄▀▀▌████▒▒▒▒▒▒███     ▌▄▄▀
▌    ▐▀████▐███▒▒▒▒▒▐██▌
▀▄▄▄▄▀   ▀▀████▒▒▒▒▄██▀
          ▀▀█████████▀
        ▄▄██▀██████▀█
      ▄██▀     ▀▀▀  █
     ▄█             ▐▌
 ▄▄▄▄█▌              ▀█▄▄▄▄▀▀▄
▌     ▐                ▀▀▄▄▄▀
 ▀▀▄▄▀

2017-11-26 21:49:22 - (sanic)[INFO]: Goin' Fast @ http://0.0.0.0:8080
2017-11-26 21:49:22 - (sanic)[INFO]: Starting worker [22356]
2017-11-26 21:49:22 - (sanic)[INFO]: Starting worker [22357]
2017-11-26 21:49:22 - (sanic)[INFO]: Starting worker [22358]
2017-11-26 21:49:22 - (sanic)[INFO]: Starting worker [22355]
/home/ubuntu/calculator/service/compute.py:51: RuntimeWarning: invalid value encountered in less
  points[points < -y_bounds] = np.nan
Executing <Handle <TaskStepMethWrapper object at 0x7f4506315320> created at /home/ubuntu/anaconda3/lib/python3.6/site-packages/sanic/server.py:234> took 0.232 seconds
2017-11-26 21:49:32 - (network)[INFO][129.174.182.39:19235]: GET http://54.189.255.114:8080/graph?exp=tan(x)  200 28315
/home/ubuntu/calculator/service/compute.py:51: RuntimeWarning: invalid value encountered in less
  points[points < -y_bounds] = np.nan
Executing <Handle <TaskStepMethWrapper object at 0x7f45063155f8> created at /home/ubuntu/anaconda3/lib/python3.6/site-packages/sanic/server.py:234> took 0.295 seconds
2017-11-26 21:49:46 - (network)[INFO][129.174.182.39:19235]: GET http://54.189.255.114:8080/graph?exp=tan(x)  200 28284
/home/ubuntu/calculator/service/compute.py:51: RuntimeWarning: invalid value encountered in less
  points[points < -y_bounds] = np.nan
Executing <Handle <TaskStepMethWrapper object at 0x7f45063157f0> created at /home/ubuntu/anaconda3/lib/python3.6/site-packages/sanic/server.py:234> took 0.231 seconds
2017-11-26 21:50:36 - (network)[INFO][129.174.182.76:28866]: GET http://54.189.255.114:8080/graph?exp=5x%2B2  200 19949
2017-11-26 21:50:47 - (sanic)[ERROR]: Traceback (most recent call last):
  File "/home/ubuntu/anaconda3/lib/python3.6/site-packages/sanic/server.py", line 143, in connection_timeout
    raise RequestTimeout('Request Timeout')
sanic.exceptions.RequestTimeout: Request Timeout

2017-11-26 21:51:36 - (sanic)[ERROR]: Traceback (most recent call last):
  File "/home/ubuntu/anaconda3/lib/python3.6/site-packages/sanic/server.py", line 143, in connection_timeout
    raise RequestTimeout('Request Timeout')
sanic.exceptions.RequestTimeout: Request Timeout

2017-11-26 21:51:37 - (sanic)[INFO]: Stopping worker [22357]
2017-11-26 21:51:37 - (sanic)[INFO]: Received signal SIGINT. Shutting down.
2017-11-26 21:51:37 - (sanic)[INFO]: Stopping worker [22355]
2017-11-26 21:51:37 - (sanic)[INFO]: Stopping worker [22358]
2017-11-26 21:51:37 - (sanic)[INFO]: Stopping worker [22356]
2017-11-26 21:51:37 - (sanic)[INFO]: Server Stopped
2017-11-26 21:51:43 - (sanic)[DEBUG]: 
                 ▄▄▄▄▄
        ▀▀▀██████▄▄▄       _______________
      ▄▄▄▄▄  █████████▄  /                 \
     ▀▀▀▀█████▌ ▀▐▄ ▀▐█ |   Gotta go fast!  |
   ▀▀█████▄▄ ▀██████▄██ | _________________/
   ▀▄▄▄▄▄  ▀▀█▄▀█════█▀ |/
        ▀▀▀▄  ▀▀███ ▀       ▄▄
     ▄███▀▀██▄████████▄ ▄▀▀▀▀▀▀█▌
   ██▀▄▄▄██▀▄███▀ ▀▀████      ▄██
▄▀▀▀▄██▄▀▀▌████▒▒▒▒▒▒███     ▌▄▄▀
▌    ▐▀████▐███▒▒▒▒▒▐██▌
▀▄▄▄▄▀   ▀▀████▒▒▒▒▄██▀
          ▀▀█████████▀
        ▄▄██▀██████▀█
      ▄██▀     ▀▀▀  █
     ▄█             ▐▌
 ▄▄▄▄█▌              ▀█▄▄▄▄▀▀▄
▌     ▐                ▀▀▄▄▄▀
 ▀▀▄▄▀

2017-11-26 21:51:43 - (sanic)[INFO]: Goin' Fast @ http://0.0.0.0:8080
2017-11-26 21:51:43 - (sanic)[INFO]: Starting worker [22371]
2017-11-26 21:51:43 - (sanic)[INFO]: Starting worker [22370]
2017-11-26 21:51:43 - (sanic)[INFO]: Starting worker [22373]
2017-11-26 21:51:43 - (sanic)[INFO]: Starting worker [22372]
/home/ubuntu/calculator/service/compute.py:51: RuntimeWarning: invalid value encountered in less
  points[points < -y_bounds] = np.nan
Executing <Handle <TaskStepMethWrapper object at 0x7ff1bda20160> created at /home/ubuntu/anaconda3/lib/python3.6/site-packages/sanic/server.py:234> took 0.236 seconds
2017-11-26 21:51:49 - (network)[INFO][129.174.182.39:37495]: GET http://54.189.255.114:8080/graph?exp=tan(x)  200 28315
/home/ubuntu/calculator/service/compute.py:51: RuntimeWarning: invalid value encountered in less
  points[points < -y_bounds] = np.nan
Executing <Handle <TaskStepMethWrapper object at 0x7ff1bda20240> created at /home/ubuntu/anaconda3/lib/python3.6/site-packages/sanic/server.py:234> took 0.300 seconds
2017-11-26 21:51:51 - (network)[INFO][129.174.182.39:37495]: GET http://54.189.255.114:8080/graph?exp=tan(x)  200 28284
Executing <Handle <TaskStepMethWrapper object at 0x7ff1bda20630> created at /home/ubuntu/anaconda3/lib/python3.6/site-packages/sanic/server.py:234> took 0.401 seconds
2017-11-26 21:51:54 - (network)[INFO][129.174.182.39:37495]: GET http://54.189.255.114:8080/graph?exp=tan(x)  200 28208
Executing <Handle <TaskStepMethWrapper object at 0x7ff1c63eb0f0> created at /home/ubuntu/anaconda3/lib/python3.6/site-packages/sanic/server.py:234> took 0.519 seconds
2017-11-26 21:52:15 - (network)[INFO][129.174.182.39:37495]: GET http://54.189.255.114:8080/graph?exp=tan(x)  200 28179
Executing <Handle <TaskStepMethWrapper object at 0x7ff1c63e0f28> created at /home/ubuntu/anaconda3/lib/python3.6/site-packages/sanic/server.py:234> took 0.624 seconds
2017-11-26 21:52:33 - (network)[INFO][129.174.182.39:37495]: GET http://54.189.255.114:8080/graph?exp=tan(x)  200 28138
Executing <Handle <TaskStepMethWrapper object at 0x7ff1bb697320> created at /home/ubuntu/anaconda3/lib/python3.6/site-packages/sanic/server.py:234> took 0.740 seconds
2017-11-26 21:52:35 - (network)[INFO][129.174.182.39:37495]: GET http://54.189.255.114:8080/graph?exp=tan(x)  200 28071
Executing <Handle <TaskStepMethWrapper object at 0x7ff1bd6ef400> created at /home/ubuntu/anaconda3/lib/python3.6/site-packages/sanic/server.py:234> took 0.851 seconds
2017-11-26 21:52:52 - (network)[INFO][129.174.182.39:37495]: GET http://54.189.255.114:8080/graph?exp=sin(x)  200 17587
Executing <Handle <TaskStepMethWrapper object at 0x7ff1bd6e93c8> created at /home/ubuntu/anaconda3/lib/python3.6/site-packages/sanic/server.py:234> took 0.950 seconds
2017-11-26 21:53:06 - (network)[INFO][129.174.182.39:37495]: GET http://54.189.255.114:8080/graph?exp=sin(x)  200 17589
Executing <Handle <TaskStepMethWrapper object at 0x7ff1bb697320> created at /home/ubuntu/anaconda3/lib/python3.6/site-packages/sanic/server.py:234> took 1.062 seconds
2017-11-26 21:53:28 - (network)[INFO][129.174.182.39:37495]: GET http://54.189.255.114:8080/graph?exp=x  200 20164
2017-11-26 21:54:29 - (sanic)[ERROR]: Traceback (most recent call last):
  File "/home/ubuntu/anaconda3/lib/python3.6/site-packages/sanic/server.py", line 143, in connection_timeout
    raise RequestTimeout('Request Timeout')
sanic.exceptions.RequestTimeout: Request Timeout

Executing <Handle <TaskStepMethWrapper object at 0x7ff1bda20550> created at /home/ubuntu/anaconda3/lib/python3.6/site-packages/sanic/server.py:234> took 0.234 seconds
2017-11-26 22:14:53 - (network)[INFO][174.204.6.241:1570]: GET http://54.189.255.114:8080/graph?exp=x  200 20410
2017-11-26 22:15:53 - (sanic)[ERROR]: Traceback (most recent call last):
  File "/home/ubuntu/anaconda3/lib/python3.6/site-packages/sanic/server.py", line 143, in connection_timeout
    raise RequestTimeout('Request Timeout')
sanic.exceptions.RequestTimeout: Request Timeout

/home/ubuntu/calculator/service/compute.py:51: RuntimeWarning: invalid value encountered in less
  points[points < -y_bounds] = np.nan
Executing <Handle <TaskStepMethWrapper object at 0x7ff1bda20630> created at /home/ubuntu/anaconda3/lib/python3.6/site-packages/sanic/server.py:234> took 0.221 seconds
2017-11-26 22:31:57 - (network)[INFO][129.174.182.76:42401]: GET http://54.189.255.114:8080/graph?exp=x^2  200 18490
2017-11-26 22:32:57 - (sanic)[ERROR]: Traceback (most recent call last):
  File "/home/ubuntu/anaconda3/lib/python3.6/site-packages/sanic/server.py", line 143, in connection_timeout
    raise RequestTimeout('Request Timeout')
sanic.exceptions.RequestTimeout: Request Timeout

Executing <Handle <TaskStepMethWrapper object at 0x7ff1bda20438> created at /home/ubuntu/anaconda3/lib/python3.6/site-packages/sanic/server.py:234> took 0.231 seconds
2017-11-26 23:05:18 - (network)[INFO][174.204.6.241:11214]: GET http://54.189.255.114:8080/graph?exp=x  200 20410
2017-11-26 23:06:18 - (sanic)[ERROR]: Traceback (most recent call last):
  File "/home/ubuntu/anaconda3/lib/python3.6/site-packages/sanic/server.py", line 143, in connection_timeout
    raise RequestTimeout('Request Timeout')
sanic.exceptions.RequestTimeout: Request Timeout

2017-11-26 23:06:19 - (sanic)[INFO]: Received signal SIGTERM. Shutting down.
2017-11-26 23:06:19 - (sanic)[INFO]: Stopping worker [22372]
2017-11-26 23:06:19 - (sanic)[INFO]: Stopping worker [22373]
2017-11-26 23:06:19 - (sanic)[INFO]: Stopping worker [22370]
2017-11-26 23:06:19 - (sanic)[INFO]: Stopping worker [22371]
2017-11-26 23:06:19 - (sanic)[INFO]: Server Stopped
2017-11-29 02:31:45 - (sanic)[DEBUG]: 
                 ▄▄▄▄▄
        ▀▀▀██████▄▄▄       _______________
      ▄▄▄▄▄  █████████▄  /                 \
     ▀▀▀▀█████▌ ▀▐▄ ▀▐█ |   Gotta go fast!  |
   ▀▀█████▄▄ ▀██████▄██ | _________________/
   ▀▄▄▄▄▄  ▀▀█▄▀█════█▀ |/
        ▀▀▀▄  ▀▀███ ▀       ▄▄
     ▄███▀▀██▄████████▄ ▄▀▀▀▀▀▀█▌
   ██▀▄▄▄██▀▄███▀ ▀▀████      ▄██
▄▀▀▀▄██▄▀▀▌████▒▒▒▒▒▒███     ▌▄▄▀
▌    ▐▀████▐███▒▒▒▒▒▐██▌
▀▄▄▄▄▀   ▀▀████▒▒▒▒▄██▀
          ▀▀█████████▀
        ▄▄██▀██████▀█
      ▄██▀     ▀▀▀  █
     ▄█             ▐▌
 ▄▄▄▄█▌              ▀█▄▄▄▄▀▀▄
▌     ▐                ▀▀▄▄▄▀
 ▀▀▄▄▀

2017-11-29 02:31:45 - (sanic)[INFO]: Goin' Fast @ http://0.0.0.0:8080
2017-11-29 02:31:45 - (sanic)[ERROR]: Experienced exception while trying to serve
Traceback (most recent call last):
  File "/home/ubuntu/anaconda3/lib/python3.6/site-packages/sanic/app.py", line 597, in run
    serve_multiple(server_settings, workers)
  File "/home/ubuntu/anaconda3/lib/python3.6/site-packages/sanic/server.py", line 584, in serve_multiple
    sock.bind((server_settings['host'], server_settings['port']))
OSError: [Errno 98] Address already in use
Traceback (most recent call last):
  File "server.py", line 58, in <module>
    debug=True
  File "/home/ubuntu/anaconda3/lib/python3.6/site-packages/sanic/app.py", line 597, in run
    serve_multiple(server_settings, workers)
  File "/home/ubuntu/anaconda3/lib/python3.6/site-packages/sanic/server.py", line 584, in serve_multiple
    sock.bind((server_settings['host'], server_settings['port']))
OSError: [Errno 98] Address already in use
2017-11-29 02:32:30 - (sanic)[DEBUG]: 
                 ▄▄▄▄▄
        ▀▀▀██████▄▄▄       _______________
      ▄▄▄▄▄  █████████▄  /                 \
     ▀▀▀▀█████▌ ▀▐▄ ▀▐█ |   Gotta go fast!  |
   ▀▀█████▄▄ ▀██████▄██ | _________________/
   ▀▄▄▄▄▄  ▀▀█▄▀█════█▀ |/
        ▀▀▀▄  ▀▀███ ▀       ▄▄
     ▄███▀▀██▄████████▄ ▄▀▀▀▀▀▀█▌
   ██▀▄▄▄██▀▄███▀ ▀▀████      ▄██
▄▀▀▀▄██▄▀▀▌████▒▒▒▒▒▒███     ▌▄▄▀
▌    ▐▀████▐███▒▒▒▒▒▐██▌
▀▄▄▄▄▀   ▀▀████▒▒▒▒▄██▀
          ▀▀█████████▀
        ▄▄██▀██████▀█
      ▄██▀     ▀▀▀  █
     ▄█             ▐▌
 ▄▄▄▄█▌              ▀█▄▄▄▄▀▀▄
▌     ▐                ▀▀▄▄▄▀
 ▀▀▄▄▀

2017-11-29 02:32:30 - (sanic)[INFO]: Goin' Fast @ http://0.0.0.0:8080
2017-11-29 02:32:30 - (sanic)[INFO]: Starting worker [1717]
2017-11-29 02:32:30 - (sanic)[INFO]: Starting worker [1715]
2017-11-29 02:32:30 - (sanic)[INFO]: Starting worker [1718]
2017-11-29 02:32:30 - (sanic)[INFO]: Starting worker [1716]
2017-11-29 02:32:46 - (network)[INFO][129.174.182.4:17316]: GET http://54.189.255.114:8080/solve?exp=2x  200 4
/home/ubuntu/calculator/service/compute.py:51: RuntimeWarning:

invalid value encountered in less

Executing <Handle <TaskStepMethWrapper object at 0x7f9438a39940> created at /home/ubuntu/anaconda3/lib/python3.6/site-packages/sanic/server.py:234> took 3.474 seconds
2017-11-29 02:32:53 - (network)[INFO][129.174.182.4:39975]: GET http://54.189.255.114:8080/graph?exp=4x  200 18301
2017-11-29 02:33:14 - (network)[INFO][192.5.215.213:38474]: GET http://54.189.255.114:8080/solve?exp=3x  200 4
2017-11-29 02:33:46 - (sanic)[ERROR]: Traceback (most recent call last):
  File "/home/ubuntu/anaconda3/lib/python3.6/site-packages/sanic/server.py", line 143, in connection_timeout
    raise RequestTimeout('Request Timeout')
sanic.exceptions.RequestTimeout: Request Timeout

2017-11-29 02:33:53 - (sanic)[ERROR]: Traceback (most recent call last):
  File "/home/ubuntu/anaconda3/lib/python3.6/site-packages/sanic/server.py", line 143, in connection_timeout
    raise RequestTimeout('Request Timeout')
sanic.exceptions.RequestTimeout: Request Timeout

2017-11-29 02:34:14 - (sanic)[ERROR]: Traceback (most recent call last):
  File "/home/ubuntu/anaconda3/lib/python3.6/site-packages/sanic/server.py", line 143, in connection_timeout
    raise RequestTimeout('Request Timeout')
sanic.exceptions.RequestTimeout: Request Timeout

2017-11-29 02:34:18 - (sanic)[ERROR]: Traceback (most recent call last):
  File "/home/ubuntu/anaconda3/lib/python3.6/site-packages/sanic/server.py", line 143, in connection_timeout
    raise RequestTimeout('Request Timeout')
sanic.exceptions.RequestTimeout: Request Timeout

2017-11-29 02:34:18 - (sanic)[ERROR]: Traceback (most recent call last):
  File "/home/ubuntu/anaconda3/lib/python3.6/site-packages/sanic/server.py", line 143, in connection_timeout
    raise RequestTimeout('Request Timeout')
sanic.exceptions.RequestTimeout: Request Timeout

2017-11-29 02:34:18 - (sanic)[ERROR]: Traceback (most recent call last):
  File "/home/ubuntu/anaconda3/lib/python3.6/site-packages/sanic/server.py", line 143, in connection_timeout
    raise RequestTimeout('Request Timeout')
sanic.exceptions.RequestTimeout: Request Timeout

2017-11-29 02:35:27 - (network)[INFO][129.174.182.2:12877]: GET http://54.189.255.114:8080/solve?exp=56-4  200 4
2017-11-29 02:35:32 - (network)[INFO][129.174.182.2:12877]: GET http://54.189.255.114:8080/solve?exp=52.0/5  200 4
2017-11-29 02:35:38 - (network)[INFO][129.174.182.2:12877]: GET http://54.189.255.114:8080/solve?exp=10.4%2B13  200 4
2017-11-29 02:35:51 - (sanic)[ERROR]: Traceback (most recent call last):
  File "/home/ubuntu/anaconda3/lib/python3.6/site-packages/sanic/app.py", line 503, in handle_request
    response = await response
  File "/home/ubuntu/anaconda3/lib/python3.6/asyncio/coroutines.py", line 109, in __next__
    return self.gen.send(None)
  File "server.py", line 37, in solve
    solution = calculator.solve(expression)
  File "/home/ubuntu/calculator/service/compute.py", line 134, in solve
    result = operation(*operands)
AttributeError: 'NoneType' object has no attribute 'tan'

2017-11-29 02:35:51 - (sanic)[ERROR]: Exception occurred while handling uri: "http://54.189.255.114:8080/solve?exp=tan(x)"
Traceback (most recent call last):
  File "/home/ubuntu/anaconda3/lib/python3.6/site-packages/sanic/app.py", line 503, in handle_request
    response = await response
  File "/home/ubuntu/anaconda3/lib/python3.6/asyncio/coroutines.py", line 109, in __next__
    return self.gen.send(None)
  File "server.py", line 37, in solve
    solution = calculator.solve(expression)
  File "/home/ubuntu/calculator/service/compute.py", line 134, in solve
    result = operation(*operands)
AttributeError: 'NoneType' object has no attribute 'tan'

2017-11-29 02:35:51 - (network)[INFO][129.174.182.2:20180]: GET http://54.189.255.114:8080/solve?exp=tan(x)  500 2726
2017-11-29 02:35:55 - (network)[INFO][129.174.182.4:2117]: GET http://54.189.255.114:8080/solve?exp=2x  200 4
2017-11-29 02:35:57 - (sanic)[ERROR]: Traceback (most recent call last):
  File "/home/ubuntu/anaconda3/lib/python3.6/site-packages/sanic/app.py", line 503, in handle_request
    response = await response
  File "/home/ubuntu/anaconda3/lib/python3.6/asyncio/coroutines.py", line 109, in __next__
    return self.gen.send(None)
  File "server.py", line 37, in solve
    solution = calculator.solve(expression)
  File "/home/ubuntu/calculator/service/compute.py", line 134, in solve
    result = operation(*operands)
AttributeError: 'NoneType' object has no attribute 'tan'

2017-11-29 02:35:57 - (sanic)[ERROR]: Exception occurred while handling uri: "http://54.189.255.114:8080/solve?exp=tan(x)"
Traceback (most recent call last):
  File "/home/ubuntu/anaconda3/lib/python3.6/site-packages/sanic/app.py", line 503, in handle_request
    response = await response
  File "/home/ubuntu/anaconda3/lib/python3.6/asyncio/coroutines.py", line 109, in __next__
    return self.gen.send(None)
  File "server.py", line 37, in solve
    solution = calculator.solve(expression)
  File "/home/ubuntu/calculator/service/compute.py", line 134, in solve
    result = operation(*operands)
AttributeError: 'NoneType' object has no attribute 'tan'

2017-11-29 02:35:57 - (network)[INFO][129.174.182.2:20180]: GET http://54.189.255.114:8080/solve?exp=tan(x)  500 2726
2017-11-29 02:36:38 - (sanic)[ERROR]: Traceback (most recent call last):
  File "/home/ubuntu/anaconda3/lib/python3.6/site-packages/sanic/server.py", line 143, in connection_timeout
    raise RequestTimeout('Request Timeout')
sanic.exceptions.RequestTimeout: Request Timeout

2017-11-29 02:36:44 - (sanic)[ERROR]: Traceback (most recent call last):
  File "/home/ubuntu/anaconda3/lib/python3.6/site-packages/sanic/app.py", line 503, in handle_request
    response = await response
  File "/home/ubuntu/anaconda3/lib/python3.6/asyncio/coroutines.py", line 109, in __next__
    return self.gen.send(None)
  File "server.py", line 37, in solve
    solution = calculator.solve(expression)
  File "/home/ubuntu/calculator/service/compute.py", line 134, in solve
    result = operation(*operands)
AttributeError: 'NoneType' object has no attribute 'tan'

2017-11-29 02:36:44 - (sanic)[ERROR]: Exception occurred while handling uri: "http://54.189.255.114:8080/solve?exp=tan(x)"
Traceback (most recent call last):
  File "/home/ubuntu/anaconda3/lib/python3.6/site-packages/sanic/app.py", line 503, in handle_request
    response = await response
  File "/home/ubuntu/anaconda3/lib/python3.6/asyncio/coroutines.py", line 109, in __next__
    return self.gen.send(None)
  File "server.py", line 37, in solve
    solution = calculator.solve(expression)
  File "/home/ubuntu/calculator/service/compute.py", line 134, in solve
    result = operation(*operands)
AttributeError: 'NoneType' object has no attribute 'tan'

2017-11-29 02:36:44 - (network)[INFO][129.174.182.2:20180]: GET http://54.189.255.114:8080/solve?exp=tan(x)  500 2726
2017-11-29 02:36:55 - (sanic)[ERROR]: Traceback (most recent call last):
  File "/home/ubuntu/anaconda3/lib/python3.6/site-packages/sanic/server.py", line 143, in connection_timeout
    raise RequestTimeout('Request Timeout')
sanic.exceptions.RequestTimeout: Request Timeout

2017-11-29 02:37:01 - (network)[INFO][129.174.182.2:20180]: GET http://54.189.255.114:8080/solve?exp=x  200 4
2017-11-29 02:37:13 - (sanic)[ERROR]: Traceback (most recent call last):
  File "/home/ubuntu/anaconda3/lib/python3.6/site-packages/sanic/app.py", line 493, in handle_request
    handler, args, kwargs, uri = self.router.get(request)
  File "/home/ubuntu/anaconda3/lib/python3.6/site-packages/sanic/router.py", line 307, in get
    return self._get(request.path, request.method, '')
  File "/home/ubuntu/anaconda3/lib/python3.6/site-packages/sanic/router.py", line 356, in _get
    raise NotFound('Requested URL {} not found'.format(url))
sanic.exceptions.NotFound: Requested URL / not found

2017-11-29 02:37:13 - (network)[INFO][129.174.182.2:20180]: GET http://54.189.255.114:8080/  404 32
2017-11-29 02:37:22 - (sanic)[ERROR]: Traceback (most recent call last):
  File "/home/ubuntu/anaconda3/lib/python3.6/site-packages/sanic/app.py", line 493, in handle_request
    handler, args, kwargs, uri = self.router.get(request)
  File "/home/ubuntu/anaconda3/lib/python3.6/site-packages/sanic/router.py", line 307, in get
    return self._get(request.path, request.method, '')
  File "/home/ubuntu/anaconda3/lib/python3.6/site-packages/sanic/router.py", line 356, in _get
    raise NotFound('Requested URL {} not found'.format(url))
sanic.exceptions.NotFound: Requested URL / not found

2017-11-29 02:37:22 - (network)[INFO][129.174.182.2:41588]: GET http://54.189.255.114:8080/  404 32
2017-11-29 02:37:23 - (network)[INFO][192.5.215.213:34377]: GET http://54.189.255.114:8080/solve?exp=2x  200 4
/home/ubuntu/calculator/service/compute.py:51: RuntimeWarning:

invalid value encountered in less

Executing <Handle <TaskStepMethWrapper object at 0x7f9438a3bd30> created at /home/ubuntu/anaconda3/lib/python3.6/site-packages/sanic/server.py:234> took 3.655 seconds
2017-11-29 02:37:23 - (sanic)[ERROR]: Connection lost before response written @ ('129.174.182.2', 20180)
/home/ubuntu/calculator/service/compute.py:51: RuntimeWarning:

invalid value encountered in less

Executing <Handle <TaskStepMethWrapper object at 0x7f9438a39860> created at /home/ubuntu/anaconda3/lib/python3.6/site-packages/sanic/server.py:234> took 2.902 seconds
2017-11-29 02:37:33 - (network)[INFO][129.174.182.2:41588]: GET http://54.189.255.114:8080/graph?exp=tan(x)  200 28315
/home/ubuntu/calculator/service/compute.py:51: RuntimeWarning:

invalid value encountered in less

Executing <Handle <TaskStepMethWrapper object at 0x7f943d11bcc0> created at /home/ubuntu/anaconda3/lib/python3.6/site-packages/sanic/server.py:234> took 2.896 seconds
2017-11-29 02:37:36 - (network)[INFO][129.174.182.2:41588]: GET http://54.189.255.114:8080/graph?exp=tan(x)  200 28284
2017-11-29 02:37:42 - (network)[INFO][192.5.215.213:34377]: GET http://54.189.255.114:8080/solve?exp=x  200 4
2017-11-29 02:37:48 - (network)[INFO][129.174.182.2:22560]: GET http://54.189.255.114:8080/solve?exp=459/8  200 6
2017-11-29 02:37:54 - (network)[INFO][129.174.182.2:41588]: GET http://54.189.255.114:8080/solve?exp=7%2B9  200 4
2017-11-29 02:37:58 - (network)[INFO][129.174.182.2:41588]: GET http://54.189.255.114:8080/solve?exp=7x  200 4
/home/ubuntu/calculator/service/compute.py:51: RuntimeWarning:

invalid value encountered in less

Executing <Handle <TaskStepMethWrapper object at 0x7f9438a396d8> created at /home/ubuntu/anaconda3/lib/python3.6/site-packages/sanic/server.py:234> took 3.154 seconds
2017-11-29 02:38:06 - (network)[INFO][129.174.182.4:15401]: GET http://54.189.255.114:8080/solve?exp=x  200 4
2017-11-29 02:38:06 - (network)[INFO][129.174.182.76:23056]: GET http://54.189.255.114:8080/graph?exp=5x  200 20135
/home/ubuntu/calculator/service/compute.py:51: RuntimeWarning:

invalid value encountered in less

Executing <Handle <TaskStepMethWrapper object at 0x7f9438a397f0> created at /home/ubuntu/anaconda3/lib/python3.6/site-packages/sanic/server.py:234> took 3.761 seconds
2017-11-29 02:38:21 - (network)[INFO][129.174.182.76:23056]: GET http://54.189.255.114:8080/graph?exp=2x  200 18396
2017-11-29 02:38:43 - (sanic)[ERROR]: Traceback (most recent call last):
  File "/home/ubuntu/anaconda3/lib/python3.6/site-packages/sanic/server.py", line 143, in connection_timeout
    raise RequestTimeout('Request Timeout')
sanic.exceptions.RequestTimeout: Request Timeout

2017-11-29 02:38:45 - (network)[INFO][192.5.215.213:47203]: GET http://54.189.255.114:8080/solve?exp=x  200 4
2017-11-29 02:38:48 - (sanic)[ERROR]: Traceback (most recent call last):
  File "/home/ubuntu/anaconda3/lib/python3.6/site-packages/sanic/server.py", line 143, in connection_timeout
    raise RequestTimeout('Request Timeout')
sanic.exceptions.RequestTimeout: Request Timeout

2017-11-29 02:38:57 - (sanic)[ERROR]: Traceback (most recent call last):
  File "/home/ubuntu/anaconda3/lib/python3.6/site-packages/sanic/server.py", line 143, in connection_timeout
    raise RequestTimeout('Request Timeout')
sanic.exceptions.RequestTimeout: Request Timeout

2017-11-29 02:39:00 - (sanic)[ERROR]: Traceback (most recent call last):
  File "/home/ubuntu/anaconda3/lib/python3.6/site-packages/sanic/server.py", line 143, in connection_timeout
    raise RequestTimeout('Request Timeout')
sanic.exceptions.RequestTimeout: Request Timeout

2017-11-29 02:39:01 - (sanic)[ERROR]: Traceback (most recent call last):
  File "/home/ubuntu/anaconda3/lib/python3.6/site-packages/sanic/server.py", line 143, in connection_timeout
    raise RequestTimeout('Request Timeout')
sanic.exceptions.RequestTimeout: Request Timeout

2017-11-29 02:39:07 - (network)[INFO][192.5.215.213:47203]: GET http://54.189.255.114:8080/solve?exp=x  200 4
2017-11-29 02:39:22 - (sanic)[ERROR]: Traceback (most recent call last):
  File "/home/ubuntu/anaconda3/lib/python3.6/site-packages/sanic/server.py", line 143, in connection_timeout
    raise RequestTimeout('Request Timeout')
sanic.exceptions.RequestTimeout: Request Timeout

2017-11-29 02:39:36 - (network)[INFO][129.174.182.2:50110]: GET http://54.189.255.114:8080/solve?exp=57.3753-985  200 9
/home/ubuntu/calculator/service/compute.py:134: RuntimeWarning:

divide by zero encountered in true_divide

2017-11-29 02:39:42 - (network)[INFO][129.174.182.2:50110]: GET http://54.189.255.114:8080/solve?exp=-927.6247/0  200 4
2017-11-29 02:39:48 - (network)[INFO][129.174.182.2:50110]: GET http://54.189.255.114:8080/solve?exp=1/0  200 3
2017-11-29 02:39:58 - (network)[INFO][129.174.182.2:50110]: GET http://54.189.255.114:8080/solve?exp=123/0  200 3
2017-11-29 02:40:01 - (network)[INFO][129.174.182.2:50110]: GET http://54.189.255.114:8080/solve?exp=inf%2B3  200 4
Executing <Handle <TaskStepMethWrapper object at 0x7f9438a39908> created at /home/ubuntu/anaconda3/lib/python3.6/site-packages/sanic/server.py:234> took 4.188 seconds
2017-11-29 02:40:05 - (network)[INFO][192.5.215.213:47203]: GET http://54.189.255.114:8080/graph?exp=x  200 20313
2017-11-29 02:41:00 - (sanic)[ERROR]: Traceback (most recent call last):
  File "/home/ubuntu/anaconda3/lib/python3.6/site-packages/sanic/server.py", line 143, in connection_timeout
    raise RequestTimeout('Request Timeout')
sanic.exceptions.RequestTimeout: Request Timeout

2017-11-29 02:41:05 - (sanic)[ERROR]: Traceback (most recent call last):
  File "/home/ubuntu/anaconda3/lib/python3.6/site-packages/sanic/server.py", line 143, in connection_timeout
    raise RequestTimeout('Request Timeout')
sanic.exceptions.RequestTimeout: Request Timeout

Executing <Handle <TaskStepMethWrapper object at 0x7f9449862198> created at /home/ubuntu/anaconda3/lib/python3.6/site-packages/sanic/server.py:234> took 3.584 seconds
2017-11-29 02:41:09 - (network)[INFO][192.5.215.213:42448]: GET http://54.189.255.114:8080/graph?exp=tanx  200 28208
Executing <Handle <TaskStepMethWrapper object at 0x7f9438a36860> created at /home/ubuntu/anaconda3/lib/python3.6/site-packages/sanic/server.py:234> took 3.839 seconds
2017-11-29 02:42:13 - (network)[INFO][192.5.215.213:51905]: GET http://54.189.255.114:8080/graph?exp=x  200 20362
2017-11-29 02:42:20 - (sanic)[ERROR]: Traceback (most recent call last):
  File "/home/ubuntu/anaconda3/lib/python3.6/site-packages/plotly/api/v1/utils.py", line 22, in validate_response
    parsed_content = response.json()
  File "/home/ubuntu/anaconda3/lib/python3.6/site-packages/requests/models.py", line 892, in json
    return complexjson.loads(self.text, **kwargs)
  File "/home/ubuntu/anaconda3/lib/python3.6/json/__init__.py", line 354, in loads
    return _default_decoder.decode(s)
  File "/home/ubuntu/anaconda3/lib/python3.6/json/decoder.py", line 339, in decode
    obj, end = self.raw_decode(s, idx=_w(s, 0).end())
  File "/home/ubuntu/anaconda3/lib/python3.6/json/decoder.py", line 357, in raw_decode
    raise JSONDecodeError("Expecting value", s, err.value) from None
json.decoder.JSONDecodeError: Expecting value: line 2 column 1 (char 1)

During handling of the above exception, another exception occurred:

Traceback (most recent call last):
  File "/home/ubuntu/anaconda3/lib/python3.6/site-packages/sanic/app.py", line 503, in handle_request
    response = await response
  File "/home/ubuntu/anaconda3/lib/python3.6/asyncio/coroutines.py", line 109, in __next__
    return self.gen.send(None)
  File "server.py", line 25, in graph
    calculator.graph(expression, 'temp.png')
  File "/home/ubuntu/calculator/service/compute.py", line 53, in graph
    self.create_plot(increments, points, y_bounds, file_name)
  File "/home/ubuntu/calculator/service/compute.py", line 81, in create_plot
    url = g.create_graph('cs-321-project','Graph',t2)
  File "/home/ubuntu/calculator/service/plotly_lib.py", line 34, in create_graph
    plot_url=py.plot(fig, filename=graph_name, fileopt="new")
  File "/home/ubuntu/anaconda3/lib/python3.6/site-packages/plotly/plotly/plotly.py", line 233, in plot
    response = v1.clientresp(data, **plot_options)
  File "/home/ubuntu/anaconda3/lib/python3.6/site-packages/plotly/api/v1/clientresp.py", line 35, in clientresp
    response = request('post', url, data=payload)
  File "/home/ubuntu/anaconda3/lib/python3.6/site-packages/plotly/api/v1/utils.py", line 86, in request
    validate_response(response)
  File "/home/ubuntu/anaconda3/lib/python3.6/site-packages/plotly/api/v1/utils.py", line 25, in validate_response
    raise exceptions.PlotlyRequestError(message, status_code, content)
plotly.exceptions.PlotlyRequestError: 
<html><head>
<meta http-equiv="content-type" content="text/html;charset=utf-8">
<title>502 Server Error</title>
</head>
<body text=#000000 bgcolor=#ffffff>
<h1>Error: Server Error</h1>
<h2>The server encountered a temporary error and could not complete your request.<p>Please try again in 30 seconds.</h2>
<h2></h2>
</body></html>


2017-11-29 02:42:20 - (sanic)[ERROR]: Exception occurred while handling uri: "http://54.189.255.114:8080/graph?exp=tanx"
Traceback (most recent call last):
  File "/home/ubuntu/anaconda3/lib/python3.6/site-packages/plotly/api/v1/utils.py", line 22, in validate_response
    parsed_content = response.json()
  File "/home/ubuntu/anaconda3/lib/python3.6/site-packages/requests/models.py", line 892, in json
    return complexjson.loads(self.text, **kwargs)
  File "/home/ubuntu/anaconda3/lib/python3.6/json/__init__.py", line 354, in loads
    return _default_decoder.decode(s)
  File "/home/ubuntu/anaconda3/lib/python3.6/json/decoder.py", line 339, in decode
    obj, end = self.raw_decode(s, idx=_w(s, 0).end())
  File "/home/ubuntu/anaconda3/lib/python3.6/json/decoder.py", line 357, in raw_decode
    raise JSONDecodeError("Expecting value", s, err.value) from None
json.decoder.JSONDecodeError: Expecting value: line 2 column 1 (char 1)

During handling of the above exception, another exception occurred:

Traceback (most recent call last):
  File "/home/ubuntu/anaconda3/lib/python3.6/site-packages/sanic/app.py", line 503, in handle_request
    response = await response
  File "/home/ubuntu/anaconda3/lib/python3.6/asyncio/coroutines.py", line 109, in __next__
    return self.gen.send(None)
  File "server.py", line 25, in graph
    calculator.graph(expression, 'temp.png')
  File "/home/ubuntu/calculator/service/compute.py", line 53, in graph
    self.create_plot(increments, points, y_bounds, file_name)
  File "/home/ubuntu/calculator/service/compute.py", line 81, in create_plot
    url = g.create_graph('cs-321-project','Graph',t2)
  File "/home/ubuntu/calculator/service/plotly_lib.py", line 34, in create_graph
    plot_url=py.plot(fig, filename=graph_name, fileopt="new")
  File "/home/ubuntu/anaconda3/lib/python3.6/site-packages/plotly/plotly/plotly.py", line 233, in plot
    response = v1.clientresp(data, **plot_options)
  File "/home/ubuntu/anaconda3/lib/python3.6/site-packages/plotly/api/v1/clientresp.py", line 35, in clientresp
    response = request('post', url, data=payload)
  File "/home/ubuntu/anaconda3/lib/python3.6/site-packages/plotly/api/v1/utils.py", line 86, in request
    validate_response(response)
  File "/home/ubuntu/anaconda3/lib/python3.6/site-packages/plotly/api/v1/utils.py", line 25, in validate_response
    raise exceptions.PlotlyRequestError(message, status_code, content)
plotly.exceptions.PlotlyRequestError: 
<html><head>
<meta http-equiv="content-type" content="text/html;charset=utf-8">
<title>502 Server Error</title>
</head>
<body text=#000000 bgcolor=#ffffff>
<h1>Error: Server Error</h1>
<h2>The server encountered a temporary error and could not complete your request.<p>Please try again in 30 seconds.</h2>
<h2></h2>
</body></html>


2017-11-29 02:42:20 - (network)[INFO][192.5.215.213:42448]: GET http://54.189.255.114:8080/graph?exp=tanx  500 5343
Executing <Handle <TaskStepMethWrapper object at 0x7f9435f65f98> created at /home/ubuntu/anaconda3/lib/python3.6/site-packages/sanic/server.py:234> took 33.015 seconds
/home/ubuntu/calculator/service/compute.py:51: RuntimeWarning:

invalid value encountered in less

Executing <Handle <TaskStepMethWrapper object at 0x7f9449862198> created at /home/ubuntu/anaconda3/lib/python3.6/site-packages/sanic/server.py:234> took 2.997 seconds
2017-11-29 02:42:22 - (network)[INFO][192.5.215.213:51905]: GET http://54.189.255.114:8080/graph?exp=tanx  200 28208
2017-11-29 02:42:25 - (sanic)[ERROR]: Traceback (most recent call last):
  File "/home/ubuntu/anaconda3/lib/python3.6/site-packages/sanic/app.py", line 503, in handle_request
    response = await response
  File "/home/ubuntu/anaconda3/lib/python3.6/asyncio/coroutines.py", line 109, in __next__
    return self.gen.send(None)
  File "server.py", line 37, in solve
    solution = calculator.solve(expression)
  File "/home/ubuntu/calculator/service/compute.py", line 134, in solve
    result = operation(*operands)
AttributeError: 'NoneType' object has no attribute 'tan'

2017-11-29 02:42:25 - (sanic)[ERROR]: Exception occurred while handling uri: "http://54.189.255.114:8080/solve?exp=tan(x)"
Traceback (most recent call last):
  File "/home/ubuntu/anaconda3/lib/python3.6/site-packages/sanic/app.py", line 503, in handle_request
    response = await response
  File "/home/ubuntu/anaconda3/lib/python3.6/asyncio/coroutines.py", line 109, in __next__
    return self.gen.send(None)
  File "server.py", line 37, in solve
    solution = calculator.solve(expression)
  File "/home/ubuntu/calculator/service/compute.py", line 134, in solve
    result = operation(*operands)
AttributeError: 'NoneType' object has no attribute 'tan'

2017-11-29 02:42:25 - (network)[INFO][129.174.182.76:49240]: GET http://54.189.255.114:8080/solve?exp=tan(x)  500 2726
Executing <Handle <TaskStepMethWrapper object at 0x7f9438a399b0> created at /home/ubuntu/anaconda3/lib/python3.6/site-packages/sanic/server.py:234> took 3.334 seconds
2017-11-29 02:42:30 - (network)[INFO][192.5.215.213:51905]: GET http://54.189.255.114:8080/graph?exp=sinx  200 17704
2017-11-29 02:43:03 - (network)[INFO][129.174.182.76:49240]: GET http://54.189.255.114:8080/solve?exp=5^2  200 4
2017-11-29 02:43:10 - (network)[INFO][129.174.182.76:49240]: GET http://54.189.255.114:8080/solve?exp=25.08*98  200 7
2017-11-29 02:43:27 - (network)[INFO][129.174.182.2:35838]: GET http://54.189.255.114:8080/solve?exp=7x  200 4
2017-11-29 02:43:30 - (sanic)[ERROR]: Traceback (most recent call last):
  File "/home/ubuntu/anaconda3/lib/python3.6/site-packages/sanic/server.py", line 143, in connection_timeout
    raise RequestTimeout('Request Timeout')
sanic.exceptions.RequestTimeout: Request Timeout

2017-11-29 02:43:35 - (sanic)[ERROR]: Traceback (most recent call last):
  File "/home/ubuntu/anaconda3/lib/python3.6/site-packages/sanic/app.py", line 503, in handle_request
    response = await response
  File "/home/ubuntu/anaconda3/lib/python3.6/asyncio/coroutines.py", line 109, in __next__
    return self.gen.send(None)
  File "server.py", line 37, in solve
    solution = calculator.solve(expression)
  File "/home/ubuntu/calculator/service/compute.py", line 139, in solve
    return eval_stack.pop()
IndexError: pop from empty list

2017-11-29 02:43:35 - (sanic)[ERROR]: Exception occurred while handling uri: "http://54.189.255.114:8080/solve?exp=tanx"
Traceback (most recent call last):
  File "/home/ubuntu/anaconda3/lib/python3.6/site-packages/sanic/app.py", line 503, in handle_request
    response = await response
  File "/home/ubuntu/anaconda3/lib/python3.6/asyncio/coroutines.py", line 109, in __next__
    return self.gen.send(None)
  File "server.py", line 37, in solve
    solution = calculator.solve(expression)
  File "/home/ubuntu/calculator/service/compute.py", line 139, in solve
    return eval_stack.pop()
IndexError: pop from empty list

2017-11-29 02:43:35 - (network)[INFO][129.174.182.2:35838]: GET http://54.189.255.114:8080/solve?exp=tanx  500 2670
2017-11-29 02:44:10 - (sanic)[ERROR]: Traceback (most recent call last):
  File "/home/ubuntu/anaconda3/lib/python3.6/site-packages/sanic/server.py", line 143, in connection_timeout
    raise RequestTimeout('Request Timeout')
sanic.exceptions.RequestTimeout: Request Timeout

2017-11-29 02:44:36 - (sanic)[ERROR]: Traceback (most recent call last):
  File "/home/ubuntu/anaconda3/lib/python3.6/site-packages/sanic/server.py", line 143, in connection_timeout
    raise RequestTimeout('Request Timeout')
sanic.exceptions.RequestTimeout: Request Timeout

Executing <Handle <TaskStepMethWrapper object at 0x7f9438a39908> created at /home/ubuntu/anaconda3/lib/python3.6/site-packages/sanic/server.py:234> took 3.802 seconds
2017-11-29 02:46:44 - (network)[INFO][129.174.182.4:52264]: GET http://54.189.255.114:8080/graph?exp=3x  200 18603
2017-11-29 02:47:45 - (sanic)[ERROR]: Traceback (most recent call last):
  File "/home/ubuntu/anaconda3/lib/python3.6/site-packages/sanic/server.py", line 143, in connection_timeout
    raise RequestTimeout('Request Timeout')
sanic.exceptions.RequestTimeout: Request Timeout

2017-11-29 02:48:08 - (network)[INFO][129.174.182.2:4558]: GET http://54.189.255.114:8080/solve?exp=36-9  200 4
2017-11-29 02:49:08 - (sanic)[ERROR]: Traceback (most recent call last):
  File "/home/ubuntu/anaconda3/lib/python3.6/site-packages/sanic/server.py", line 143, in connection_timeout
    raise RequestTimeout('Request Timeout')
sanic.exceptions.RequestTimeout: Request Timeout

2017-11-29 02:50:53 - (network)[INFO][129.174.182.76:50391]: GET http://54.189.255.114:8080/solve?exp=5x  200 4
Executing <Handle <TaskStepMethWrapper object at 0x7f94345ede48> created at /home/ubuntu/anaconda3/lib/python3.6/site-packages/sanic/server.py:234> took 2.999 seconds
2017-11-29 02:51:35 - (sanic)[ERROR]: Connection lost before response written @ ('129.174.182.76', 50391)
Executing <Handle <TaskStepMethWrapper object at 0x7f94346bbb00> created at /home/ubuntu/anaconda3/lib/python3.6/site-packages/sanic/server.py:234> took 3.168 seconds
2017-11-29 02:51:56 - (network)[INFO][129.174.182.76:46930]: GET http://54.189.255.114:8080/graph?exp=5x  200 19983
Executing <Handle <TaskStepMethWrapper object at 0x7f94345fd390> created at /home/ubuntu/anaconda3/lib/python3.6/site-packages/sanic/server.py:234> took 3.284 seconds
2017-11-29 02:52:07 - (network)[INFO][129.174.182.76:46930]: GET http://54.189.255.114:8080/graph?exp=5x  200 19930
Executing <Handle <TaskStepMethWrapper object at 0x7f9434519ac8> created at /home/ubuntu/anaconda3/lib/python3.6/site-packages/sanic/server.py:234> took 3.569 seconds
2017-11-29 02:52:59 - (network)[INFO][129.174.182.76:46930]: GET http://54.189.255.114:8080/graph?exp=5x  200 19908
Executing <Handle <TaskStepMethWrapper object at 0x7f94345d9be0> created at /home/ubuntu/anaconda3/lib/python3.6/site-packages/sanic/server.py:234> took 3.518 seconds
2017-11-29 02:53:23 - (network)[INFO][129.174.182.76:46930]: GET http://54.189.255.114:8080/graph?exp=5x  200 19914
Executing <Handle <TaskStepMethWrapper object at 0x7f9438a3bba8> created at /home/ubuntu/anaconda3/lib/python3.6/site-packages/sanic/server.py:234> took 2.870 seconds
2017-11-29 02:53:42 - (network)[INFO][129.174.182.4:19552]: GET http://54.189.255.114:8080/graph?exp=x  200 20362
2017-11-29 02:54:23 - (sanic)[ERROR]: Traceback (most recent call last):
  File "/home/ubuntu/anaconda3/lib/python3.6/site-packages/sanic/server.py", line 143, in connection_timeout
    raise RequestTimeout('Request Timeout')
sanic.exceptions.RequestTimeout: Request Timeout

2017-11-29 02:54:43 - (sanic)[ERROR]: Traceback (most recent call last):
  File "/home/ubuntu/anaconda3/lib/python3.6/site-packages/sanic/server.py", line 143, in connection_timeout
    raise RequestTimeout('Request Timeout')
sanic.exceptions.RequestTimeout: Request Timeout

2017-11-29 02:59:04 - (sanic)[INFO]: Stopping worker [1716]
2017-11-29 02:59:09 - (sanic)[INFO]: Received signal SIGTERM. Shutting down.
2017-11-29 02:59:09 - (sanic)[INFO]: Stopping worker [1715]
2017-11-29 02:59:09 - (sanic)[INFO]: Stopping worker [1718]
2017-11-29 02:59:09 - (sanic)[INFO]: Stopping worker [1717]
2017-11-29 02:59:09 - (sanic)[INFO]: Server Stopped
